
=====================================================================
This module is intended solely for building or source activating user
python environments, i.e.,

    mamba create -n myenv -c conda-forge

or

    source activate myenv

To list available environments, run:

    mamba info --envs

See our docs: https://links.asu.edu/solpy

Any other use is NOT TESTED.
=====================================================================

  
Starting goldminer/Instance_3.jsonl with zero_shot
  0%|          | 0/489 [00:00<?, ?it/s]  0%|          | 0/489 [00:04<?, ?it/s]
Traceback (most recent call last):
  File "/home/dhanda/projects/reasoning_about_actions/reasoning_about_actions/src/evaluation/prompting/gemini.py", line 40, in <module>
    response = get_response('gemini-pro', prompt)
  File "/home/dhanda/projects/reasoning_about_actions/reasoning_about_actions/src/evaluation/prompting/helper.py", line 97, in get_response
    response = model.generate_content(prompt)
  File "/home/dhanda/.conda/envs/reasoning_about_actions/lib/python3.10/site-packages/google/generativeai/generative_models.py", line 241, in generate_content
    self._client = client.get_default_generative_client()
  File "/home/dhanda/.conda/envs/reasoning_about_actions/lib/python3.10/site-packages/google/generativeai/client.py", line 230, in get_default_generative_client
    return _client_manager.get_default_client("generative")
  File "/home/dhanda/.conda/envs/reasoning_about_actions/lib/python3.10/site-packages/google/generativeai/client.py", line 161, in get_default_client
    client = self.make_client(name)
  File "/home/dhanda/.conda/envs/reasoning_about_actions/lib/python3.10/site-packages/google/generativeai/client.py", line 121, in make_client
    client = cls(**self.client_config)
  File "/home/dhanda/.conda/envs/reasoning_about_actions/lib/python3.10/site-packages/google/ai/generativelanguage_v1beta/services/generative_service/client.py", line 433, in __init__
    self._transport = Transport(
  File "/home/dhanda/.conda/envs/reasoning_about_actions/lib/python3.10/site-packages/google/ai/generativelanguage_v1beta/services/generative_service/transports/grpc.py", line 150, in __init__
    super().__init__(
  File "/home/dhanda/.conda/envs/reasoning_about_actions/lib/python3.10/site-packages/google/ai/generativelanguage_v1beta/services/generative_service/transports/base.py", line 98, in __init__
    credentials, _ = google.auth.default(
  File "/home/dhanda/.conda/envs/reasoning_about_actions/lib/python3.10/site-packages/google/auth/_default.py", line 691, in default
    raise exceptions.DefaultCredentialsError(_CLOUD_SDK_MISSING_CREDENTIALS)
google.auth.exceptions.DefaultCredentialsError: Your default credentials were not found. To set up Application Default Credentials, see https://cloud.google.com/docs/authentication/external/set-up-adc for more information.
Starting goldminer/Instance_3.jsonl with few_shot
  0%|          | 0/489 [00:00<?, ?it/s]  0%|          | 0/489 [00:03<?, ?it/s]
Traceback (most recent call last):
  File "/home/dhanda/projects/reasoning_about_actions/reasoning_about_actions/src/evaluation/prompting/gemini.py", line 40, in <module>
    response = get_response('gemini-pro', prompt)
  File "/home/dhanda/projects/reasoning_about_actions/reasoning_about_actions/src/evaluation/prompting/helper.py", line 97, in get_response
    response = model.generate_content(prompt)
  File "/home/dhanda/.conda/envs/reasoning_about_actions/lib/python3.10/site-packages/google/generativeai/generative_models.py", line 241, in generate_content
    self._client = client.get_default_generative_client()
  File "/home/dhanda/.conda/envs/reasoning_about_actions/lib/python3.10/site-packages/google/generativeai/client.py", line 230, in get_default_generative_client
    return _client_manager.get_default_client("generative")
  File "/home/dhanda/.conda/envs/reasoning_about_actions/lib/python3.10/site-packages/google/generativeai/client.py", line 161, in get_default_client
    client = self.make_client(name)
  File "/home/dhanda/.conda/envs/reasoning_about_actions/lib/python3.10/site-packages/google/generativeai/client.py", line 121, in make_client
    client = cls(**self.client_config)
  File "/home/dhanda/.conda/envs/reasoning_about_actions/lib/python3.10/site-packages/google/ai/generativelanguage_v1beta/services/generative_service/client.py", line 433, in __init__
    self._transport = Transport(
  File "/home/dhanda/.conda/envs/reasoning_about_actions/lib/python3.10/site-packages/google/ai/generativelanguage_v1beta/services/generative_service/transports/grpc.py", line 150, in __init__
    super().__init__(
  File "/home/dhanda/.conda/envs/reasoning_about_actions/lib/python3.10/site-packages/google/ai/generativelanguage_v1beta/services/generative_service/transports/base.py", line 98, in __init__
    credentials, _ = google.auth.default(
  File "/home/dhanda/.conda/envs/reasoning_about_actions/lib/python3.10/site-packages/google/auth/_default.py", line 691, in default
    raise exceptions.DefaultCredentialsError(_CLOUD_SDK_MISSING_CREDENTIALS)
google.auth.exceptions.DefaultCredentialsError: Your default credentials were not found. To set up Application Default Credentials, see https://cloud.google.com/docs/authentication/external/set-up-adc for more information.
Starting goldminer/Instance_3.jsonl with few_shot_cot
  0%|          | 0/489 [00:00<?, ?it/s]  0%|          | 0/489 [00:03<?, ?it/s]
Traceback (most recent call last):
  File "/home/dhanda/projects/reasoning_about_actions/reasoning_about_actions/src/evaluation/prompting/gemini.py", line 40, in <module>
    response = get_response('gemini-pro', prompt)
  File "/home/dhanda/projects/reasoning_about_actions/reasoning_about_actions/src/evaluation/prompting/helper.py", line 97, in get_response
    response = model.generate_content(prompt)
  File "/home/dhanda/.conda/envs/reasoning_about_actions/lib/python3.10/site-packages/google/generativeai/generative_models.py", line 241, in generate_content
    self._client = client.get_default_generative_client()
  File "/home/dhanda/.conda/envs/reasoning_about_actions/lib/python3.10/site-packages/google/generativeai/client.py", line 230, in get_default_generative_client
    return _client_manager.get_default_client("generative")
  File "/home/dhanda/.conda/envs/reasoning_about_actions/lib/python3.10/site-packages/google/generativeai/client.py", line 161, in get_default_client
    client = self.make_client(name)
  File "/home/dhanda/.conda/envs/reasoning_about_actions/lib/python3.10/site-packages/google/generativeai/client.py", line 121, in make_client
    client = cls(**self.client_config)
  File "/home/dhanda/.conda/envs/reasoning_about_actions/lib/python3.10/site-packages/google/ai/generativelanguage_v1beta/services/generative_service/client.py", line 433, in __init__
    self._transport = Transport(
  File "/home/dhanda/.conda/envs/reasoning_about_actions/lib/python3.10/site-packages/google/ai/generativelanguage_v1beta/services/generative_service/transports/grpc.py", line 150, in __init__
    super().__init__(
  File "/home/dhanda/.conda/envs/reasoning_about_actions/lib/python3.10/site-packages/google/ai/generativelanguage_v1beta/services/generative_service/transports/base.py", line 98, in __init__
    credentials, _ = google.auth.default(
  File "/home/dhanda/.conda/envs/reasoning_about_actions/lib/python3.10/site-packages/google/auth/_default.py", line 691, in default
    raise exceptions.DefaultCredentialsError(_CLOUD_SDK_MISSING_CREDENTIALS)
google.auth.exceptions.DefaultCredentialsError: Your default credentials were not found. To set up Application Default Credentials, see https://cloud.google.com/docs/authentication/external/set-up-adc for more information.
